Workbook
Name Date_updated: Performance!$G$1:$G$2
Name MarketCapExposureTable: Exposure!$G$1:$I$6
Name NetExposureTable: Exposure!$A$1:$B$4
Name PerformanceChartTable: Table1[#All]
Name SectorExposureTable: Exposure!$D$1:$E$10
Name Statisticstable: Stats!$A$1:$B$10
Name TextBlocksTable: Text!$A$1:$B$5
Name TheFundTable: TheFund!$A$1:$B$10

Sheet Instructions - New month
B2: 1. update the separate fund spreadsheets in "Newsletter Data > Convserions" for the latest months performance
B3: (1b. Attentus will send ARF performance to portfolioadmin in the 'NAV pack')
B4: 2. In this excel doc, go to the sheet 'Performance Data' and update final row, take a note of the latest month's number in column A
B5: 3. In the 'Summary' sheet, update cell A1 for the latest month number (eg. '148' would update for sep22 numbers)
B6: 4. in the 'contribution data' sheet, update the red text for the latest month's contribution data. Do this by C&P from IRESS using 'commands > IPS > reporting > Performance Contribution)
B7: see screenshot for settings configuration - > if you cant see these settings, click on brown filter
B8: 5. Check each of the funds tabs for any data feed errors. If a new stock has been added, it may need to go into the 'Names' sheet
B9: 6. Once spreadsheet has been updated, open up the pp preso doc for each fund, click 'update links' on entry.
B10: 7. Ensure data is feeding correctly

Sheet Newsletter
A2: 45961
D17: NET PERFORMANCE | H17: MTD | J17: QTD | L17: INCEPTION | N17: ANNUALISED
D18: LASER BEAM FUND | H18: =INDEX(Performancedata!C:C, MATCH(A2, Performancedata!A:A, 0)) -> 0.031903325 | J18: =INDEX(Performancedata!E:E, MATCH(A2, Performancedata!A:A, 0)) -> 0.09100306 | L18: =INDEX(Performancedata!F:F, MATCH(A2, Performancedata!A:A, 0)) -> 0.12002374 | N18: =INDEX(Performancedata!H:H, MATCH(A2, Performancedata!A:A, 0)) -> 0.40371255
D43: TOP HOLDINGS
D44: GET FROM CELL R109
S111: TOP HOLDINGS | X111: TOP CONTRIBUTORS | AC111: THE FUND
S112: Alphabet | X112: Alphabet | AC112: Universe | AF112: Global
S113: Alphabet | X113: Alphabet | AC113: Holdings | AF113: 5-20
S114: Alphabet | X114: Alphabet | AC114: Target | AF114: >10% net p.a.
S115: Alphabet | X115: Alphabet | AC115: Min Investment | AF115: $100k
AC116: Mgmt. Fee | AF116: 0.01
S117: Net Exposure | X117: TOP DETRACTORS | AC117: Perf. Fee | AF117: 0.2
S118: Gross Long | V118: =5916039/15000000 -> 0.3944026 | X118: Alphabet | AC118: APIR | AF118: NCC5451AU
S119: Gross Short | V119: -0.16 | X119: Alphabet | AC119: Vehicle | AF119: Wholesale Unit Trust
S120: Net Exposure | V120: =V118+V119 -> 0.2344026 | X120: Alphabet | AC120: PM | AF120: Hayden Beamish
S125: TOP HOLDINGS | X125: STATISTICS | AC125: THE FUND
S126: Amazon | V126: 0.1 | X126: Best Month | AA126: 0.030806066 | AC126: Universe | AF126: Global
S127: Alphabet | V127: 0.09 | X127: Worst Month | AA127: 0.023183324 | AC127: Holdings | AF127: 5-20
S128: Reddit | V128: 0.08 | X128: MSCI AW Best | AA128: 0.031659106 | AC128: Target | AF128: >10% net p.a.
S129: United Health | V129: 0.07 | X129: MSCI AW Worst | AA129: 0.0069610812 | AC129: Min Investment | AF129: $100k
X130: Upside Capture | AA130: 1.7279211 | AC130: Mgmt. Fee | AF130: 0.01
S131: Net Exposure | X131: Downside Capture | AA131: - | AC131: Perf. Fee | AF131: 0.2
S132: Gross Long | V132: 0.85 | X132: Avg. Net Exposure | AA132: 0.45 | AC132: APIR | AF132: NCC5451AU
S133: Gross Short | V133: -0.16 | X133: Avg. Cash Balance | AA133: 0.55 | AC133: Vehicle | AF133: Wholesale Unit Trust
S134: Net Exposure | V134: =V132+V133 -> 0.69 | X134: Beta | AA134: -0.017766367 | AC134: PM | AF134: Hayden Beamish

Sheet Performancedata
C1: LBF DATA | S1: MGWD DATA | AD1: LBF Data | AP1: MSCI DATA | AZ1: HEDGE DATA
A2: Month | B2: NAV | C2: Month | D2: Inception | E2: Quarter | F2: FY | G2: 1 Yr | H2: LBF Annualised | I2: Annualised Std Dev | J2: Gain/Pain | K2: Annualised Sortino | L2: Annualised Sharpe Ratio | M2: Best Month | N2: Worst Month | O2: Upside Capture | P2: Downside Capture | Q2: Beta (fund vs benchmark) | R2: MGWD Index | S2: MGWD Month | T2: MGWD Inception | U2: MGWD 1 Yr | V2: MGWD Annualised | W2: Std Dev | X2: Gain/Pain | Y2: Benchmark annualised Sortino | Z2: Benchmark annualised Sharpe | AA2: Best Month | AB2: Worst Month | AD2: Hurdle | AE2: Rf Rate | AF2: Rf Monthly | AG2: Monthly Excess Return | AH2: Rolling 12 Months Ex Ret | AI2: Neg. Exc. Ret. | AJ2: Square Neg. Exc. Ret. | AK2: Monthly downside deviation of excess | AL2: Annualised downside deviation | AM2: Mean Monthly Excess | AN2: Stdev Excess | AO2: Sharpe Annualised | AP2: Correlation | AQ2: R squared | AR2: Tracking error | AS2: Information ratio (annualised): | AV2: Monthly Excess Return | AW2: Rolling 12 Months Ex Ret | AX2: Neg. Exc. Ret. | AY2: Square Neg. Exc. Ret. | AZ2: Monthly downside deviation of benchmark excess | BA2: Annualised downside deviation benchmark | BB2: Sharpe Excess | BC2: Monthly stdev of benchmark excess returns | BD2: Annualised stdev of benchmark excess | BF2: Weighted Avg. Market Cap ($m) | BG2: Holdings | BH2: Avg. Daily Liquidity | BI2: Cash | BJ2: Avg. Cash | BK2: NAV | BL2: Long Equities | BM2: Short Equities | BN2: Cash | BO2: Gross Exposure | BP2: Net Exposure | BQ2: Gross Long | BR2: Gross Short | BS2: Gross Exposure | BT2: Net Exposure | BU2: Avg Gross Exposure % | BV2: Avg Net Exposure % | BX2: SECTOR WEIGHTINGS | CB2: MARKET CAP BREAKDOWN
A3: 45838 | B3: 1 | D3: 0 | R3: =[1]Benchmarks!C3 -> 425.45 | BX3: Cash | BY3: =BZ3/$BZ$11 -> #DIV/0! | BZ3: 17068298 | CB3: Portfolio By Market Cap | CD3: Energy | CE3: GOOG US | CF3: GOOG US EQUITY | CG3: 0.060051455 | CI3: {=_xll.BDP(CF3,"CUR_MKT_CAP","CURRENCY","AUD")} -> 3863262380000 | CJ3: 3.4395168e+12 | CK3: =CG3/$CG$16 -> #DIV/0!
A4: 45869 | B4: 1.0266 | C4: =B4/B3-1 -> 0.0266 | D4: =((1+C4)*(1))-1 -> 0.0266 | F4: =D4 -> 0.0266 | G4: =D4 -> 0.0266 | H4: =((1+D4)^(365/(_xlfn.DAYS(A4,"1/07/2025"))))-1 -> 0.37630703 | I4: =IFERROR(_xlfn.STDEV.S($C$4:C4)*SQRT(12),"") | J4: =IFERROR(SUMIF(C$4:C4,">0",C$4:C4)/ABS(SUMIF(C$4:C4,"<0",C$4:C4)),"") | K4: =IFERROR(AVERAGE($AG$4:AG4)/AK4*SQRT(12),"") | L4: =IFERROR(AVERAGE($AG$4:AG4)/_xlfn.STDEV.S($AG$4:AG4)*SQRT(12),"") | M4: =MAX($C$4:C4) -> 0.0266 | N4: =MIN($C$4:C4) -> 0.0266 | O4: =IFERROR(AVERAGEIF($S$4:S4,">0",$C$4:C4)/AVERAGEIF($S$4:S4,">0",$S$4:S4),"") -> 0.83891549 | P4: =IFERROR(AVERAGEIF($S$4:S4,"<0",$C$4:C4)/AVERAGEIF($S$4:S4,"<0",$S$4:S4),"-") -> - | Q4: =IFERROR(SLOPE($C$4:C4,$S$4:S4),"") | R4: =[1]Benchmarks!C4 -> 438.94 | S4: =R4/R3-1 -> 0.031707604 | T4: =((1+S4)*(1+T3))-1 -> 0.031707604 | V4: =((1+T4)^(365/(_xlfn.DAYS(A4,"30/06/2025"))))-1 -> 0.44417027 | W4: =IFERROR(STDEV($S$4:S4),"") | X4: =IFERROR(SUMIF(S$4:S4,">0",S$4:S4)/ABS(SUMIF(S$4:S4,"<0",S$4:S4)),"") | Y4: =IFERROR(AVERAGE($AV$4:AV4)/AZ4*SQRT(12),"") | Z4: =IFERROR(AVERAGE($AV$4:AV4)/_xlfn.STDEV.S($AV$4:AV4)*SQRT(12),"") | AA4: =MAX($S$4:S4) -> 0.031707604 | AB4: =MIN($S$4:S4) -> 0.031707604 | AD4: 0 | AE4: 0.0385 | AF4: =((1+AE4)^(1/12))-1 -> 0.0031530742 | AG4: =C4-AF4 -> 0.023446926 | AH4: =G4-(AF4*12) -> -0.011236891 | AI4: =IF(AG4<0, AG4, "") | AJ4: =IFERROR(AI4*AI4,0) -> 0 | AK4: {=IFERROR(SQRT(AVERAGE(IF($AG$4:AG4<0,($AG$4:AG4)^2,0))),"")} -> 0 | AL4: =IFERROR(AK4*SQRT(12),"") -> 0 | AM4: =IFERROR(AVERAGE($AG$4:AG4),"") -> 0.023446926 | AN4: =IFERROR(_xlfn.STDEV.S($AG$4:AG4),"") | AO4: =IFERROR(AM4/AN4*SQRT(12),"") | AP4: =IFERROR(CORREL($C$4:C4,$S$4:S4),"") | AQ4: =IFERROR(RSQ($C$4:C4,$S$4:S4),"") | AR4: {=IFERROR(_xlfn.STDEV.S($C$4:C4-$S$4:S4)*SQRT(12),"")} | AS4: {=IFERROR((AVERAGE($C$4:C4-$S$4:S4)*12)/(_xlfn.STDEV.S($C$4:C4-$S$4:S4)*SQRT(12)),"")} | AV4: =S4-AF4 -> 0.02855453 | AW4: =U4-(AF4*12) -> -0.037836891 | AX4: =IF(AV4<0, AV4, "") | AY4: =IFERROR(AX4*AX4,0) -> 0 | AZ4: {=IFERROR(SQRT(AVERAGE(IF($AV$4:AV4<0,($AV$4:AV4)^2,0))),"")} -> 0 | BA4: =IFERROR(AZ4*SQRT(12),"") -> 0 | BB4: =IFERROR(AV4*AV4,0) -> 0.00081536116 | BC4: =IFERROR(_xlfn.STDEV.S($AV$4:AV4),"") | BD4: =IFERROR(BC4*SQRT(12),"") | BI4: =BN4/BK4 -> 0.76509668 | BJ4: =AVERAGE($BI$4:BI4) -> 0.76509668 | BK4: 14435005 | BL4: 3335141 | BM4: 55688 | BN4: 11044174 | BO4: =BL4+BM4 -> 3390829 | BP4: =BL4-BM4 -> 3279453 | BQ4: =BL4/BK4 -> 0.23104537 | BR4: =-BM4/BK4 -> -0.0038578442 | BS4: =BO4/BK4 -> 0.23490321 | BT4: =BP4/BK4 -> 0.22718752 | BU4: =AVERAGE($BS$4:BS4) -> 0.23490321 | BV4: =AVERAGE($BT$4:BT4) -> 0.22718752 | BX4: COMMUNICATIONS | BY4: =BZ4/$BZ$11 -> #DIV/0! | BZ4: 1412895.3 | CB4: =">$10b (" & TEXT(CC4,"0%") & ")" -> #DIV/0! | CC4: {=SUMPRODUCT((CJ$3:CJ$15>=10000000000)*CK$3:CK$15)} -> #DIV/0! | CD4: China | CE4: IBKR US | CF4: IBKR US EQUITY | CG4: 0.054955813 | CI4: {=_xll.BDP(CF4,"CUR_MKT_CAP","CURRENCY","AUD")} -> 1.1052994e+11 | CJ4: 1.1875764e+11 | CK4: =CG4/$CG$16 -> #DIV/0!
A5: 45900 | B5: 1.0504 | C5: =B5/B4-1 -> 0.023183324 | D5: =((1+C5)*(1+D4))-1 -> 0.0504 | E5: =((1+C5)*(1+C4)*(1+C3)-1) -> 0.0504 | F5: =D5 -> 0.0504 | G5: =D5 -> 0.0504 | H5: =((1+D5)^(365/(_xlfn.DAYS(A5,"1/07/2025"))))-1 -> 0.34207937 | I5: =IFERROR(_xlfn.STDEV.S($C$4:C5)*SQRT(12),"") -> 0.0083691138 | J5: =IFERROR(SUMIF(C$4:C5,">0",C$4:C5)/ABS(SUMIF(C$4:C5,"<0",C$4:C5)),"") | K5: =IFERROR(AVERAGE($AG$4:AG5)/AK5*SQRT(12),"") | L5: =IFERROR(AVERAGE($AG$4:AG5)/_xlfn.STDEV.S($AG$4:AG5)*SQRT(12),"") -> 33.27631 | M5: =MAX($C$4:C5) -> 0.0266 | N5: =MIN($C$4:C5) -> 0.023183324 | O5: =IFERROR(AVERAGEIF($S$4:S5,">0",$C$4:C5)/AVERAGEIF($S$4:S5,">0",$S$4:S5),"") -> 1.2531382 | P5: =IFERROR(AVERAGEIF($S$4:S5,"<0",$C$4:C5)/AVERAGEIF($S$4:S5,"<0",$S$4:S5),"-") -> - | Q5: =IFERROR(SLOPE($C$4:C5,$S$4:S5),"") -> 0.14423486 | R5: =[1]Benchmarks!C5 -> 442.46 | S5: =R5/R4-1 -> 0.0080193193 | T5: =((1+S5)*(1+T4))-1 -> 0.039981196 | V5: =((1+T5)^(365/(_xlfn.DAYS(A5,"30/06/2025"))))-1 -> 0.25959431 | W5: =IFERROR(STDEV($S$4:S5),"") -> 0.016750147 | X5: =IFERROR(SUMIF(S$4:S5,">0",S$4:S5)/ABS(SUMIF(S$4:S5,"<0",S$4:S5)),"") | Y5: =IFERROR(AVERAGE($AV$4:AV5)/AZ5*SQRT(12),"") | Z5: =IFERROR(AVERAGE($AV$4:AV5)/_xlfn.STDEV.S($AV$4:AV5)*SQRT(12),"") -> 3.5065339 | AA5: =MAX($S$4:S5) -> 0.031707604 | AB5: =MIN($S$4:S5) -> 0.0080193193 | AD5: 0 | AE5: 0.036 | AF5: =((1+AE5)^(1/12))-1 -> 0.0029516094 | AG5: =C5-AF5 -> 0.020231714 | AH5: =G5-(AF5*12) -> 0.014980687 | AI5: =IF(AG5<0, AG5, "") | AJ5: =IFERROR(AI5*AI5,0) -> 0 | AK5: {=IFERROR(SQRT(AVERAGE(IF($AG$4:AG5<0,($AG$4:AG5)^2,0))),"")} -> 0 | AL5: =IFERROR(AK5*SQRT(12),"") -> 0 | AM5: =IFERROR(AVERAGE($AG$4:AG5),"") -> 0.02183932 | AN5: =IFERROR(_xlfn.STDEV.S($AG$4:AG5),"") -> 0.0022734979 | AO5: =IFERROR(AM5/AN5*SQRT(12),"") -> 33.27631 | AP5: =IFERROR(CORREL($C$4:C5,$S$4:S5),"") -> 1 | AQ5: =IFERROR(RSQ($C$4:C5,$S$4:S5),"") -> 1 | AR5: {=IFERROR(_xlfn.STDEV.S($C$4:C5-$S$4:S5)*SQRT(12),"")} -> 0.049655096 | AS5: {=IFERROR((AVERAGE($C$4:C5-$S$4:S5)*12)/(_xlfn.STDEV.S($C$4:C5-$S$4:S5)*SQRT(12)),"")} -> 1.2151503 | AV5: =S5-AF5 -> 0.0050677098 | AW5: =U5-(AF5*12) -> -0.035419313 | AX5: =IF(AV5<0, AV5, "") | AY5: =IFERROR(AX5*AX5,0) -> 0 | AZ5: {=IFERROR(SQRT(AVERAGE(IF($AV$4:AV5<0,($AV$4:AV5)^2,0))),"")} -> 0 | BA5: =IFERROR(AZ5*SQRT(12),"") -> 0 | BB5: =IFERROR(AV5*AV5,0) -> 2.5681683e-05 | BC5: =IFERROR(_xlfn.STDEV.S($AV$4:AV5),"") -> 0.016607689 | BD5: =IFERROR(BC5*SQRT(12),"") -> 0.057530724 | BI5: =BN5/BK5 -> 0.6342679 | BJ5: =AVERAGE($BI$4:BI5) -> 0.69968229 | BK5: 16535083 | BL5: 6363581 | BM5: 1778665 | BN5: 10487672 | BO5: =BL5+BM5 -> 8142246 | BP5: =BL5-BM5 -> 4584916 | BQ5: =BL5/BK5 -> 0.38485328 | BR5: =-BM5/BK5 -> -0.10756916 | BS5: =BO5/BK5 -> 0.49242245 | BT5: =BP5/BK5 -> 0.27728412 | BU5: =AVERAGE($BS$4:BS5) -> 0.36366283 | BV5: =AVERAGE($BT$4:BT5) -> 0.25223582 | BX5: FINANCIALS | BY5: =BZ5/$BZ$11 -> #DIV/0! | BZ5: 1399028.2 | CB5: ="$1b-$10b (" & TEXT(CC5,"0%") & ")" -> #DIV/0! | CC5: {=SUMPRODUCT((CJ$3:CJ$15>=1000000000)*(CJ$3:CJ$15<10000000000)*CK$3:CK$15)} -> #DIV/0! | CD5: AI | CE5: 9988 HK | CF5: 9988 HK EQUITY | CG5: 0.051390242 | CI5: {=_xll.BDP(CF5,"CUR_MKT_CAP","CURRENCY","AUD")} -> 2.9568299e+12 | CJ5: 3149566246860 | CK5: =CG5/$CG$16 -> #DIV/0!
A6: 45930 | B6: 1.085396 | C6: =B6/B5-1 -> 0.033316832 | D6: =((1+C6)*(1+D5))-1 -> 0.085396 | E6: =((1+C6)*(1+C5)*(1+C4)-1) -> 0.085396 | F6: =D6 -> 0.085396 | G6: =D6 -> 0.085396 | H6: =((1+D6)^(365/(_xlfn.DAYS(A6,"1/07/2025"))))-1 -> 0.38913338 | I6: =IFERROR(_xlfn.STDEV.S($C$4:C6)*SQRT(12),"") -> 0.017859311 | J6: =IFERROR(SUMIF(C$4:C6,">0",C$4:C6)/ABS(SUMIF(C$4:C6,"<0",C$4:C6)),"") | K6: =IFERROR(AVERAGE($AG$4:AG6)/AK6*SQRT(12),"") | L6: =IFERROR(AVERAGE($AG$4:AG6)/_xlfn.STDEV.S($AG$4:AG6)*SQRT(12),"") -> 16.510936 | M6: =MAX($C$4:C6) -> 0.033316832 | N6: =MIN($C$4:C6) -> 0.023183324 | O6: =IFERROR(AVERAGEIF($S$4:S6,">0",$C$4:C6)/AVERAGEIF($S$4:S6,">0",$S$4:S6),"") -> 1.3175095 | P6: =IFERROR(AVERAGEIF($S$4:S6,"<0",$C$4:C6)/AVERAGEIF($S$4:S6,"<0",$S$4:S6),"-") -> - | Q6: =IFERROR(SLOPE($C$4:C6,$S$4:S6),"") -> 0.20797204 | R6: =[1]Benchmarks!C6 -> 452.79 | S6: =R6/R5-1 -> 0.023346743 | T6: =((1+S6)*(1+T5))-1 -> 0.06426137 | V6: =((1+T6)^(365/(_xlfn.DAYS(A6,"30/06/2025"))))-1 -> 0.28029835 | W6: =IFERROR(STDEV($S$4:S6),"") -> 0.012013664 | X6: =IFERROR(SUMIF(S$4:S6,">0",S$4:S6)/ABS(SUMIF(S$4:S6,"<0",S$4:S6)),"") | Y6: =IFERROR(AVERAGE($AV$4:AV6)/AZ6*SQRT(12),"") | Z6: =IFERROR(AVERAGE($AV$4:AV6)/_xlfn.STDEV.S($AV$4:AV6)*SQRT(12),"") -> 5.2308134 | AA6: =MAX($S$4:S6) -> 0.031707604 | AB6: =MIN($S$4:S6) -> 0.0080193193 | AD6: 0 | AE6: 0.036 | AF6: =((1+AE6)^(1/12))-1 -> 0.0029516094 | AG6: =C6-AF6 -> 0.030365222 | AH6: =G6-(AF6*12) -> 0.049976687 | AI6: =IF(AG6<0, AG6, "") | AJ6: =IFERROR(AI6*AI6,0) -> 0 | AK6: {=IFERROR(SQRT(AVERAGE(IF($AG$4:AG6<0,($AG$4:AG6)^2,0))),"")} -> 0 | AL6: =IFERROR(AK6*SQRT(12),"") -> 0 | AM6: =IFERROR(AVERAGE($AG$4:AG6),"") -> 0.024681287 | AN6: =IFERROR(_xlfn.STDEV.S($AG$4:AG6),"") -> 0.0051782944 | AO6: =IFERROR(AM6/AN6*SQRT(12),"") -> 16.510936 | AP6: =IFERROR(CORREL($C$4:C6,$S$4:S6),"") -> 0.48462561 | AQ6: =IFERROR(RSQ($C$4:C6,$S$4:S6),"") -> 0.23486198 | AR6: {=IFERROR(_xlfn.STDEV.S($C$4:C6-$S$4:S6)*SQRT(12),"")} -> 0.036476065 | AS6: {=IFERROR((AVERAGE($C$4:C6-$S$4:S6)*12)/(_xlfn.STDEV.S($C$4:C6-$S$4:S6)*SQRT(12)),"")} -> 2.1961239 | AV6: =S6-AF6 -> 0.020395134 | AW6: =U6-(AF6*12) -> -0.035419313 | AX6: =IF(AV6<0, AV6, "") | AY6: =IFERROR(AX6*AX6,0) -> 0 | AZ6: {=IFERROR(SQRT(AVERAGE(IF($AV$4:AV6<0,($AV$4:AV6)^2,0))),"")} -> 0 | BA6: =IFERROR(AZ6*SQRT(12),"") -> 0 | BB6: =IFERROR(AV6*AV6,0) -> 0.00041596148 | BC6: =IFERROR(_xlfn.STDEV.S($AV$4:AV6),"") -> 0.011924319 | BD6: =IFERROR(BC6*SQRT(12),"") -> 0.041307054 | BI6: =BN6/BK6 -> 0.64644687 | BJ6: =AVERAGE($BI$4:BI6) -> 0.68193715 | BK6: 17156638 | BL6: 7772590 | BM6: 4351270 | BN6: 11090855 | BO6: =BL6+BM6 -> 12123860 | BP6: =BL6-BM6 -> 3421320 | BQ6: =BL6/BK6 -> 0.45303689 | BR6: =-BM6/BK6 -> -0.2536202 | BS6: =BO6/BK6 -> 0.7066571 | BT6: =BP6/BK6 -> 0.19941669 | BU6: =AVERAGE($BS$4:BS6) -> 0.47799425 | BV6: =AVERAGE($BT$4:BT6) -> 0.23462945 | BX6: METALS | BY6: =BZ6/$BZ$11 -> #DIV/0! | BZ6: 1250122.2 | CB6: ="$500m-$1b (" & TEXT(CC6,"0%") & ")" -> #DIV/0! | CC6: {=SUMPRODUCT((CJ$3:CJ$15>=500000000)*(CJ$3:CJ$15<1000000000)*CK$3:CK$15)} -> #DIV/0! | CD6: Value | CE6: LLM AU | CF6: LLM AU EQUITY | CG6: 0.047334743 | CI6: {=_xll.BDP(CF6,"CUR_MKT_CAP","CURRENCY","AUD")} -> 51088575 | CJ6: 42689751 | CK6: =CG6/$CG$16 -> #DIV/0!
A7: 45961 | B7: =[2]Monthly!$G$41 -> 1.1200237 | C7: =B7/B6-1 -> 0.031903325 | D7: =((1+C7)*(1+D6))-1 -> 0.12002374 | E7: =((1+C7)*(1+C6)*(1+C5)-1) -> 0.09100306 | F7: =D7 -> 0.12002374 | G7: =D7 -> 0.12002374 | H7: =((1+D7)^(365/(_xlfn.DAYS(A7,"1/07/2025"))))-1 -> 0.40371255 | I7: =IFERROR(_xlfn.STDEV.S($C$4:C7)*SQRT(12),"") -> 0.016298441 | J7: =IFERROR(SUMIF(C$4:C7,">0",C$4:C7)/ABS(SUMIF(C$4:C7,"<0",C$4:C7)),"") | K7: =IFERROR(AVERAGE($AG$4:AG7)/AK7*SQRT(12),"") | L7: =IFERROR(AVERAGE($AG$4:AG7)/_xlfn.STDEV.S($AG$4:AG7)*SQRT(12),"") -> 18.831291 | M7: =MAX($C$4:C7) -> 0.033316832 | N7: =MIN($C$4:C7) -> 0.023183324 | O7: =IFERROR(AVERAGEIF($S$4:S7,">0",$C$4:C7)/AVERAGEIF($S$4:S7,">0",$S$4:S7),"") -> 1.1722974 | P7: =IFERROR(AVERAGEIF($S$4:S7,"<0",$C$4:C7)/AVERAGEIF($S$4:S7,"<0",$S$4:S7),"-") -> - | Q7: =IFERROR(SLOPE($C$4:C7,$S$4:S7),"") -> 0.23909152 | R7: =[1]Benchmarks!C7 -> 468.65 | S7: =R7/R6-1 -> 0.035027275 | T7: =((1+S7)*(1+T6))-1 -> 0.10153955 | V7: =((1+T7)^(365/(_xlfn.DAYS(A7,"30/06/2025"))))-1 -> 0.33239938 | W7: =IFERROR(STDEV($S$4:S7),"") -> 0.012051464 | X7: =IFERROR(SUMIF(S$4:S7,">0",S$4:S7)/ABS(SUMIF(S$4:S7,"<0",S$4:S7)),"") | Y7: =IFERROR(AVERAGE($AV$4:AV7)/AZ7*SQRT(12),"") | Z7: =IFERROR(AVERAGE($AV$4:AV7)/_xlfn.STDEV.S($AV$4:AV7)*SQRT(12),"") -> 6.2071276 | AA7: =MAX($S$4:S7) -> 0.035027275 | AB7: =MIN($S$4:S7) -> 0.0080193193 | AD7: 0 | AE7: 0.036 | AF7: =((1+AE7)^(1/12))-1 -> 0.0029516094 | AG7: =C7-AF7 -> 0.028951715 | AH7: =G7-(AF7*12) -> 0.084604428 | AI7: =IF(AG7<0, AG7, "") | AJ7: =IFERROR(AI7*AI7,0) -> 0 | AK7: {=IFERROR(SQRT(AVERAGE(IF($AG$4:AG7<0,($AG$4:AG7)^2,0))),"")} -> 0 | AL7: =IFERROR(AK7*SQRT(12),"") -> 0 | AM7: =IFERROR(AVERAGE($AG$4:AG7),"") -> 0.025748894 | AN7: =IFERROR(_xlfn.STDEV.S($AG$4:AG7),"") -> 0.0047366262 | AO7: =IFERROR(AM7/AN7*SQRT(12),"") -> 18.831291 | AP7: =IFERROR(CORREL($C$4:C7,$S$4:S7),"") -> 0.61241885 | AQ7: =IFERROR(RSQ($C$4:C7,$S$4:S7),"") -> 0.37505684 | AR7: {=IFERROR(_xlfn.STDEV.S($C$4:C7-$S$4:S7)*SQRT(12),"")} -> 0.034279581 | AS7: {=IFERROR((AVERAGE($C$4:C7-$S$4:S7)*12)/(_xlfn.STDEV.S($C$4:C7-$S$4:S7)*SQRT(12)),"")} -> 1.4792367 | AV7: =S7-AF7 -> 0.032075666 | AW7: =U7-(AF7*12) -> -0.035419313 | AX7: =IF(AV7<0, AV7, "") | AY7: =IFERROR(AX7*AX7,0) -> 0 | AZ7: {=IFERROR(SQRT(AVERAGE(IF($AV$4:AV7<0,($AV$4:AV7)^2,0))),"")} -> 0 | BA7: =IFERROR(AZ7*SQRT(12),"") -> 0 | BB7: =IFERROR(AV7*AV7,0) -> 0.0010288483 | BC7: =IFERROR(_xlfn.STDEV.S($AV$4:AV7),"") -> 0.012011797 | BD7: =IFERROR(BC7*SQRT(12),"") -> 0.041610086 | BI7: =BN7/BK7 -> 0.7746703 | BJ7: =AVERAGE($BI$4:BI7) -> 0.70512044 | BK7: 21990000 | BL7: 6370000 | BM7: 4171000 | BN7: 17035000 | BO7: 10574000 | BP7: 2231000 | BQ7: =BL7/BK7 -> 0.28967713 | BR7: =-BM7/BK7 -> -0.18967713 | BS7: =BO7/BK7 -> 0.48085493 | BT7: =BP7/BK7 -> 0.10145521 | BU7: =AVERAGE($BS$4:BS7) -> 0.47870942 | BV7: =AVERAGE($BT$4:BT7) -> 0.20133589 | BX7: CONSUMER DISCRETIONARY | BY7: =BZ7/$BZ$11 -> #DIV/0! | BZ7: 1006416.3 | CB7: ="$500m-$1b (" & TEXT(CC7,"0%") & ")" -> #DIV/0! | CC7: {=SUMPRODUCT((CJ$3:CJ$15>=500000000)*(CJ$3:CJ$15<1000000000)*CK$3:CK$15)} -> #DIV/0! | CD7: Value | CE7: RDDT US | CF7: RDDT US EQUITY | CG7: 0.047334743 | CI7: {=_xll.BDP(CF7,"CUR_MKT_CAP","CURRENCY","AUD")} -> 4.1020148e+10 | CJ7: 3.4799002e+10 | CK7: =CG7/$CG$16 -> #DIV/0!
A8: 45991 | B8: =[2]Monthly!$H$41 -> 1.1169996 | C8: =B8/B7-1 -> -0.0027000944 | D8: =((1+C8)*(1+D7))-1 -> 0.11699957 | E8: =((1+C8)*(1+C7)*(1+C6)-1) -> 0.063404009 | F8: =D8 -> 0.11699957 | G8: =D8 -> 0.11699957 | H8: =((1+D8)^(365/(_xlfn.DAYS(A8,"1/07/2025"))))-1 -> 0.30433889 | I8: =IFERROR(_xlfn.STDEV.S($C$4:C8)*SQRT(12),"") -> 0.050726925 | J8: =IFERROR(SUMIF(C$4:C8,">0",C$4:C8)/ABS(SUMIF(C$4:C8,"<0",C$4:C8)),"") -> 42.592393 | K8: =IFERROR(AVERAGE($AG$4:AG8)/AK8*SQRT(12),"") -> 26.683012 | L8: =IFERROR(AVERAGE($AG$4:AG8)/_xlfn.STDEV.S($AG$4:AG8)*SQRT(12),"") -> 4.6099449 | M8: =MAX($C$4:C8) -> 0.033316832 | N8: =MIN($C$4:C8) -> -0.0027000944 | O8: =IFERROR(AVERAGEIF($S$4:S8,">0",$C$4:C8)/AVERAGEIF($S$4:S8,">0",$S$4:S8),"") -> 1.1722974 | P8: =IFERROR(AVERAGEIF($S$4:S8,"<0",$C$4:C8)/AVERAGEIF($S$4:S8,"<0",$S$4:S8),"-") -> 1.4379537 | Q8: =IFERROR(SLOPE($C$4:C8,$S$4:S8),"") -> 0.77359491 | R8: =[1]Benchmarks!C8 -> 467.77 | S8: =R8/R7-1 -> -0.0018777339 | T8: =((1+S8)*(1+T7))-1 -> 0.099471148 | V8: =((1+T8)^(365/(_xlfn.DAYS(A8,"30/06/2025"))))-1 -> 0.25385993 | W8: =IFERROR(STDEV($S$4:S8),"") -> 0.015759178 | X8: =IFERROR(SUMIF(S$4:S8,">0",S$4:S8)/ABS(SUMIF(S$4:S8,"<0",S$4:S8)),"") -> 52.244325 | Y8: =IFERROR(AVERAGE($AV$4:AV8)/AZ8*SQRT(12),"") -> 26.068384 | Z8: =IFERROR(AVERAGE($AV$4:AV8)/_xlfn.STDEV.S($AV$4:AV8)*SQRT(12),"") -> 3.581599 | AA8: =MAX($S$4:S8) -> 0.035027275 | AB8: =MIN($S$4:S8) -> -0.0018777339 | AD8: 0 | AE8: 0.036 | AF8: =((1+AE8)^(1/12))-1 -> 0.0029516094 | AG8: =C8-AF8 -> -0.0056517038 | AH8: =G8-(AF8*12) -> 0.081580258 | AI8: =IF(AG8<0, AG8, "") -> -0.0056517038 | AJ8: =IFERROR(AI8*AI8,0) -> 3.1941756e-05 | AK8: {=IFERROR(SQRT(AVERAGE(IF($AG$4:AG8<0,($AG$4:AG8)^2,0))),"")} -> 0.0025275188 | AL8: =IFERROR(AK8*SQRT(12),"") -> 0.0087555819 | AM8: =IFERROR(AVERAGE($AG$4:AG8),"") -> 0.019468775 | AN8: =IFERROR(_xlfn.STDEV.S($AG$4:AG8),"") -> 0.014629635 | AO8: =IFERROR(AM8/AN8*SQRT(12),"") -> 4.6099449 | AP8: =IFERROR(CORREL($C$4:C8,$S$4:S8),"") -> 0.83252878 | AQ8: =IFERROR(RSQ($C$4:C8,$S$4:S8),"") -> 0.69310417 | AR8: {=IFERROR(_xlfn.STDEV.S($C$4:C8-$S$4:S8)*SQRT(12),"")} -> 0.03069975 | AS8: {=IFERROR((AVERAGE($C$4:C8-$S$4:S8)*12)/(_xlfn.STDEV.S($C$4:C8-$S$4:S8)*SQRT(12)),"")} -> 1.2570926 | AV8: =S8-AF8 -> -0.0048293433 | AW8: =U8-(AF8*12) -> -0.035419313 | AX8: =IF(AV8<0, AV8, "") -> -0.0048293433 | AY8: =IFERROR(AX8*AX8,0) -> 2.3322557e-05 | AZ8: {=IFERROR(SQRT(AVERAGE(IF($AV$4:AV8<0,($AV$4:AV8)^2,0))),"")} -> 0.002159748 | BA8: =IFERROR(AZ8*SQRT(12),"") -> 0.0074815865 | BB8: =IFERROR(AV8*AV8,0) -> 2.3322557e-05 | BC8: =IFERROR(_xlfn.STDEV.S($AV$4:AV8),"") -> 0.015719554 | BD8: =IFERROR(BC8*SQRT(12),"") -> 0.054454134 | BI8: =BN8/BK8 -> 0.7746703 | BJ8: =AVERAGE($BI$4:BI8) -> 0.71903041 | BK8: 21990000 | BL8: 6370000 | BM8: 4171000 | BN8: 17035000 | BO8: 10574000 | BP8: 2231000 | BQ8: =BL8/BK8 -> 0.28967713 | BR8: =-BM8/BK8 -> -0.18967713 | BS8: =BO8/BK8 -> 0.48085493 | BT8: =BP8/BK8 -> 0.10145521 | BU8: =AVERAGE($BS$4:BS8) -> 0.47913852 | BV8: =AVERAGE($BT$4:BT8) -> 0.18135975 | BX8: CONSUMER DISCRETIONARY | BY8: =BZ8/$BZ$11 -> #DIV/0! | BZ8: 1006416.3 | CB8: ="$500m-$1b (" & TEXT(CC8,"0%") & ")" -> #DIV/0! | CC8: {=SUMPRODUCT((CJ$3:CJ$15>=500000000)*(CJ$3:CJ$15<1000000000)*CK$3:CK$15)} -> #DIV/0! | CD8: Value | CE8: RDDT US | CF8: RDDT US EQUITY | CG8: 0.047334743 | CI8: {=_xll.BDP(CF8,"CUR_MKT_CAP","CURRENCY","AUD")} -> 4.1020148e+10 | CJ8: 3.4799002e+10 | CK8: =CG8/$CG$16 -> #DIV/0!
BQ9: COMMUNICATIONS | BR9: 0.25 | BS9: 3030428.1 | CA9: SLB | CB9: =CA9&"-NYS" -> SLB-NYS | CC9: 3.828 | CD9: =_xll.fdsb(CB9,"FREF_MARKET_VALUE_COMPANY(NOW,,,AUD,,0,,""LEGACY"")") -> #NAME? | CE9: =_xll.fdsb(CB9,"P_VOLUME_AVG(-1AY,NOW)") -> #NAME? | CF9: =_xll.fdsb(CB9,"FG_PRICE(NOW,NOW,,AUD)") -> #NAME? | CG9: =IFERROR(CF9*CE9,"") | CI9: NEA-AU | CJ9: =CC9/100 -> 0.03828 | CK9: 47094.626 | CL9: 15.83537 | CM9: 33.831615 | CN9: 535.73614 | CO9: =CN9*CJ9 -> 20.507979 | CP9: =CJ9 -> 0.03828 | CQ9: =CJ9*$CB$35 -> 11.484 | CR9: =CQ9/CN9 -> 0.021435925 | CS9: =CS8+1 -> 1 | CT9: 3 | CU9: CWP | CV9: CWP-AU | CW9: Cedar Woods Properties Limited | CX9: 0.048232 | CY9: 551.4767 | CZ9: 778.44824 | DA9: 778.44824 | DB9: 6.83 | DC9: 0.26 | DD9: 0.3461615 | DE9: 0.430136 | DF9: 0.402 | DG9: 0.33139038 | DH9: 34.72067 | DI9: 42.2 | DJ9: 55.721977 | DK9: 0.21541433 | DL9: n/a | DM9: 19.730675 | DN9: 0.24258764 | DO9: 2.5413076 | DP9: 16.250631 | DQ9: n/a | DR9: 0.320426 | DS9: 0.055345829 | DT9: n/a | DU9: Finance | DV9: Producer Manufacturing | DW9: Austal Ltd. engages in the design and construction of customized aluminum commercial and defense vessels. The company operates through the following segments: Australia, USA, and Asia. The Australia segment manufactures commercial and defense vessels for markets worldwide, excluding the USA and provides training and on-going support and maintenance for vessels. The USA segment engages in the manufacturing of aluminum defense vessels for the US Navy and provides training and on-going support and maintenance of these performance vessels for the US Navy. The Asia segment provides aluminium commercial vessels for global markets excluding the USA. The company was founded by John Rothwell in 1988 and is headquartered in Henderson, Australia. | DX9: Designs and constructs customized aluminium commercial and defence vessels
BQ10: CASH | BR10: 0.54 | BS10: 10487672 | CA10: TWTR | CB10: =CA10&"-NYS" -> TWTR-NYS | CC10: 5.5955 | CD10: =_xll.fdsb(CB10,"FREF_MARKET_VALUE_COMPANY(NOW,,,AUD,,0,,""LEGACY"")") -> #NAME? | CE10: =_xll.fdsb(CB10,"P_VOLUME_AVG(-1AY,NOW)") -> #NAME? | CF10: =_xll.fdsb(CB10,"FG_PRICE(NOW,NOW,,AUD)") -> #NAME? | CG10: =IFERROR(CF10*CE10,"") | CI10: TNE-AU | CJ10: =CC10/100 -> 0.055955 | CK10: 48421.983 | CL10: 19.870663 | CM10: 60.881382 | CN10: 1209.7534 | CO10: =CN10*CJ10 -> 67.691753 | CP10: =CJ10 -> 0.055955 | CQ10: =CJ10*$CB$35 -> 16.7865 | CR10: =CQ10/CN10 -> 0.013875968 | CS10: =CS9+1 -> 2 | CT10: 4 | CU10: BABA | CV10: BABA-NYS | CW10: Alibaba Group Holding Ltd. Sponsored ADR | CX10: 0.0512 | CY10: 717169.75 | CZ10: 723830.95 | DA10: 723830.95 | DB10: 267.25 | DC10: 7.4189215 | DD10: 10.15762 | DE10: 12.35188 | DF10: 15.349785 | DG10: 0.36915049 | DH10: 21985.258 | DI10: 32521.266 | DJ10: 41030.504 | DK10: 0.47923058 | DL10: 0.043290376 | DM10: 26.310297 | DN10: 0.21602108 | DO10: 1.1474565 | DP10: 20.67883 | DQ10: 0.30667264 | DR10: 0.2616515 | DS10: 0.2383672 | DT10: 0.14281477 | DU10: Retail Trade | DV10: Technology Services | DW10: BigTinCan Holdings Ltd. is a software development company. The company focuses on providing enterprise mobility solutions, which enables sales and service organizations to increase sales, reduce expenditures and improve customer satisfaction through mobile worker productivity. Its Bigtincan hub, mobile content engagement platform enables users to securely access and interact with all types of content such as files, documents, PDFs, powerpoint presentations, e-mail, video, RSS fees, forms, media, web content, and share knowledge and expertise across teams, and automate processes across any mobile device or network. The company provides software development services to clients in Australia and U.S. BigTinCan Holdings was founded by David Keane and Geoffrey Cohen in 2011 and is headquartered in Sydney, Australia. | DX10: Develops video distributing software
CB11: =CA11&"-NYS" -> -NYS | CP11: =CJ11 -> 0 | CQ11: =CJ11*$CB$35 -> 0 | CR11: =CQ11/CN11 -> #DIV/0! | CS11: =CS10+1 -> 3 | CT11: 5 | CU11: NWH | CV11: NWH-AU | CW11: NRW Holdings Limited | CX11: 0.046931 | CY11: 1243.7738 | CZ11: 1305.9978 | DA11: 1305.9978 | DB11: 2.895 | DC11: 0.21841 | DD11: 0.23694435 | DE11: 0.253224 | DF11: 0.23204423 | DG11: 0.084860354 | DH11: 237.68733 | DI11: 289.79962 | DJ11: 301.67307 | DK11: 0.21924724 | DL11: 0.12115896 | DM11: 12.218059 | DN11: 0.068706639 | DO11: -11.754628 | DP11: 4.3559546 | DQ11: 0.12449239 | DR11: 0.040971241 | DS11: 0.19310141 | DT11: 0.1353089 | DU11: Industrial Services | DV11: Finance | DW11: Cedar Woods Properties Ltd. engages in property investment and development. The firm's principal interests are in urban land and built form development for residential, industrial and commercial purposes. Its projects include St. A in St Albans, Jackson Green in Clayton South, Williams Landing, Bushmead, Harrisdale Green, Ellendale, and Glenside. The company was founded by William George Hames and Ross James Neumann in 1987 and is headquartered in West Perth, Australia. | DX11: Engages in property investment and development activities in Australia
CB12: =CA12&"-NYS" -> -NYS | CP12: =CJ12 -> 0 | CQ12: =CJ12*$CB$35 -> 0 | CR12: =CQ12/CN12 -> #DIV/0! | CS12: =CS11+1 -> 4 | CT12: 6 | CU12: IMD | CV12: IMD-AU | CW12: Imdex Ltd | CX12: 0.046611 | CY12: 580.8028 | CZ12: 583.15221 | DA12: 583.15221 | DB12: 1.465 | DC12: 0.0546 | DD12: 0.048333332 | DE12: 0.0665 | DF12: 0.0788 | DG12: -0.11477414 | DH12: 53.540287 | DI12: 57.8187 | DJ12: 69.24495 | DK12: 0.079910162 | DL12: 0.025036345 | DM12: 30.310346 | DN12: 0.37586211 | DO12: 1.0948308 | DP12: 9.558548 | DQ12: 0.2357673 | DR12: 0.19762205 | DS12: 0.098531849 | DT12: 0.07003083 | DU12: Distribution Services | DV12: Electronic Technology | DW12: Electro Optic Systems Holdings Ltd. develops and produces products incorporating advanced electro-optic technologies for the aerospace market. Its products are developed through internal research and development programs based on its core technologies in software, lasers, electronics, optics, gimbals, telescopes and beam directors, optical coatings and precision mechanisms. The company operates its business through the following segments: Defence Systems and Space. The Defence Systems segment develops, manufactures and markets advanced fire control, surveillance and weapon systems to approved military customers. The Space segment involves in surveillance systems. Electro Optic Systems Holdings was founded by Benny Allan Greene in 1983 and is headquartered in Sydney, Australia. | DX12: Develops and produces electro-optic technologies for the aerospace market
CT13: 7 | CU13: PAN | CV13: PAN-AU | CW13: Panoramic Resources Limited | CX13: 0.045665 | CY13: 287.12796 | CZ13: 115.89632 | DA13: 115.89632 | DB13: 0.14 | DC13: -0.050223 | DD13: -0.0025 | DE13: -0.00675 | DF13: 0.01 | DG13: 0 | DH13: -30.007 | DI13: -5.5876293 | DJ13: -0.69484264 | DK13: 0 | DL13: -0.18982483 | DM13: n/a | DN13: n/a | DO13: n/a | DP13: n/a | DQ13: -5.7309018 | DR13: 0 | DS13: -0.63179361 | DT13: -0.0296076 | DU13: Non-Energy Minerals | DV13: Distribution Services | DW13: Imdex Ltd. engages in the provision of mining equipment, technology, and services. It operates through the AMC and REFLEX brands. The AMC brand deals with drilling fluids, equipment, technologies, and software. The REFLEX brand includes downhole instrumentation, data management and analytical software for geological modelling. The company was founded on December 17, 1980 and is headquartered in Balcatta, Australia. | DX13: Provides drilling fluids to mining industries
BQ14: Total | BS14: =SUM(BS3:BS11) -> 13518103 | CT14: 8 | CU14: XLI | CV14: XLI-NYS | CW14: Industrial Select Sector SPDR Fund | CX14: 0.04369 | CY14: 16033.356 | CZ14: n/a | DA14: n/a | DB14: 89.21 | DC14: n/a | DD14: n/a | DE14: n/a | DF14: n/a | DG14: n/a | DH14: n/a | DI14: n/a | DJ14: n/a | DK14: n/a | DL14: n/a | DM14: n/a | DN14: n/a | DO14: n/a | DP14: n/a | DQ14: n/a | DR14: n/a | DS14: n/a | DT14: n/a | DU14: Miscellaneous | DV14: Communications | DW14: MNF Group Ltd. engages in the provision of voice, data, and cloud based communication and communication enablement services. It operates its business through the following segments: Domestic Retail, Domestic Wholesale, and Global Wholesale. The Domestic Retail segment involves in selling directly to residential, small business, enterprise and government customers. The Domestic Wholesale segment include selling to Australian and New Zealand domestic carriers, carriage service providers, cloud providers, and application providers. The Global Wholesale segment focuses in selling to the global carriers, carriage service providers, cloud providers, and application providers. The company was founded by Kam Kan Fung and Rene Sugo in 2004 and is headquartered in Sydney, Australia. | DX14: Provides IP based VoIP, data and video services
CT15: 9 | CU15: OBL | CV15: OBL-AU | CW15: Omni Bridgeway Ltd | CX15: 0.040918 | CY15: 1088.0491 | CZ15: 1359.7622 | DA15: 1359.7622 | DB15: 4.15 | DC15: 0.074664 | DD15: 0.6377954 | DE15: 0.5653762 | DF15: 0.5153572 | DG15: 7.5422078 | DH15: 59.880665 | DI15: 329.542 | DJ15: 326.061 | DK15: 4.5033123 | DL15: n/a | DM15: 6.5067889 | DN15: -0.11354613 | DO15: -0.64362699 | DP15: 3.5165935 | DQ15: 0.86627656 | DR15: -0.010563145 | DS15: -0.04159684 | DT15: n/a | DU15: Commercial Services | DV15: Finance | DW15: Money3 Corp. Ltd. provides financial services. Its specialization includes the delivery of small cash loans, secured and unsecured personal loans, cheque cashing, equipment and motor vehicle rental. It operates through following segments: Broker, Branch and Online. The Broker segment provides facilities based on the provision of an underlying asset as security, generally referred through a broker. The Branch segment provides services and facilities generally without the provision of an underlying asset as security through the branch network. The Online segment provides facilities without the provision of an underlying asset as security through the internet. The company was founded on November 25, 2005 and is headquartered in Bundoora, Australia. | DX15: Provides credit, personal and car cash loans, cheque cashing, international money transfer and insurance brokerage services
CT16: 10 | CU16: CAT | CV16: CAT-AU | CW16: Catapult Group International Ltd. | CX16: 0.039981 | CY16: 390.84174 | CZ16: 365.046 | DA16: 365.046 | DB16: 1.95 | DC16: -0.02793 | DD16: 0.001597521 | DE16: 0.087475486 | DF16: n/a | DG16: 0 | DH16: 13.3 | DI16: 17.821829 | DJ16: 24.802769 | DK16: 0.33998714 | DL16: 0.022803474 | DM16: 1220.6412 | DN16: 53.757018 | DO16: n/a | DP16: 20.560738 | DQ16: 0.16967746 | DR16: 0.39170727 | DS16: -0.064271088 | DT16: -0.013119726 | DU16: Commercial Services | DV16: Finance | DW16: Macquarie Group Ltd. operates as a non-operating holding company. The firm engages in the provision of banking, financial, advisory, investment and funds management services. It operates through the following segments: Macquarie Asset Management (MAM), Banking and Financial Services (BFS), Commodities and Global Markets (CGM), Macquarie Capital and Corporate. The MAM segment delivers investment solutions to clients across a range of capabilities, including infrastructure, real estate, agriculture, equities, fixed income, private credit, liquid alternatives, and multi-asset solutions. The BFS segment offers personal banking, wealth management, business banking, and vehicle finance products and services to retail clients, advisers, brokers and business clients. The CGM segment comprises of integrated, end-to-end offering across global markets including equities, fixed income, foreign exchange, and commodities. The Macquarie Capital segment includes capital solutions across products and sectors including infrastructure, green and conventional energy. The Corporate segment refers to the head office and central service groups, including group treasury and other investments. The company was founded on December 10, 1969 and is headquartered in Sydney, Australia. | DX16: Provides retail financial services, investment banking, and financial market services
CA19: Avg. market cap | CC19: =AVERAGE(CK4:CK12)/1000 -> #DIV/0! | CD19: b | CE19: 1) Update column BW to make sure ASX stocks have "-AU" after and USA stocks "-NYS" (CAT & XLI are the only 3 letter codes that are NYS)
CA20: Weighting avg. market cap | CC20: =SUMPRODUCT($CK$4:$CK$12,$CJ$4:$CJ$12)/1000 -> #DIV/0! | CD20: b | CE20: 2) Click Factset
CA21: Avg. daily value | CC21: =AVERAGE(CN4:CN12) -> 872.74478 | CD21: m
CA22: Weighting avg. daily liquidity | CC22: =SUMPRODUCT($CN$4:$CN$12,$CJ$4:$CJ$12) -> 88.199732 | CD22: m | CE22: 3) Click Hardcode
CA23: Avg AU liquidity
CE25: 5) Copy data from BX39 & BX41 into columns AW and AY
CA26: Portfolio By Market Cap
CA27: >$10b (84%) | CB27: 0.84
CA28: $1b-$10b (11%) | CB28: 0.11
CA29: $500m-$1b (0%) | CB29: =SUMIFS($CJ$4:$CJ$13,$CK$4:$CK$13,">500",$CK$4:$CK$13,"<1000") -> 0
CA30: $300m-$500m (0%) | CB30: 0
CA31: <$300m (5%) | CB31: 0.05
CA33: 300m FUM
CA34: Days to exit | CB34: % exit <2 days | CC34: 80% of $300m within two weeks
CA35: Weighting | CB35: 300
CA37: INTERACTIVE BROKERS
CA39: Energy | CC39: 0.034 | CD39: Financials | CF39: Financials | CG39: MQG-AU | CH39: 5.2453
CA40: Heathcare | CC40: 0.0565 | CD40: Software | CF40: Software | CG40: TWTR-NYS | CH40: 5.1018
CA41: Materials | CC41: 0.092 | CD41: Resources | CF41: Property | CG41: CWP-AU | CH41: 4.8232
CA42: Telecomm | CC42: 0.11 | CD42: Property | CF42: Online Retail | CG42: BABA-NYS | CH42: 5.12
CA43: Industrials | CC43: 0.157 | CD43: Online Retail | CF43: Mining Services | CG43: NWH-AU | CH43: 4.6931
CA44: Technology | CC44: 0.183 | CD44: Medical Device | CF44: Mining Services | CG44: IMD-AU | CH44: 4.6611
CA45: Financials | CC45: 0.232 | CD45: Defence Construction | CF45: Resources | CG45: PAN-AU | CH45: 4.5665
CD46: Biotechnology | CF46: Industrial | CG46: XLI-NYS | CH46: 4.369
...

Sheet Performance
A1: Month | B1: CumulativeReturn | D1: label | E1: value | G1: Date updated
A2: 45838 | B2: 0 | D2: MTD | E2: =Performancedata!C8 -> -0.0027000944 | G2: 45991
A3: 45869 | B3: 0.0266 | D3: QTD | E3: =Performancedata!E8 -> 0.063404009
A4: 45900 | B4: 0.0504 | D4: FY26 | E4: =Performancedata!D8 -> 0.11699957
A5: 45930 | B5: 0.077 | D5: Annualised | E5: =Performancedata!H8 -> 0.30433889
A6: 45961 | B6: =Performancedata!D7 -> 0.12002374
A7: 45991 | B7: =Performancedata!D8 -> 0.11699957

Sheet Holdings
A1: TopHoldingsTable | B1: Weight | C1: Rank | D1: Column1 | E1: Column2 | F1: Column3 | G1: Column4 | H1: Column5 | I1: Column6 | J1: Column7 | K1: Column8 | L1: Column9 | M1: Column10
A2: Reddit | B2: 0.046 | C2: 1
A3: South32 | B3: 0.042 | C3: 2
A4: Unity Software | B4: 0.0413 | C4: 3

Sheet Stats
A1: key | B1: value | C1: Column1 | D1: Column2
A2: Best Month | B2: 0.033316832
A3: Worst Month | B3: -0.0027000944
A4: MSCI AW Best | B4: 0.035027275
A5: MSCI AW Worst | B5: -0.0018777339
A6: Upside Capture | B6: 1.1722974
A7: Downside Capture | B7: 1.4379537
A8: Avg. Net Exposure | B8: 0.18135975
A9: Avg. Cash Balance | B9: 0.71903041
A10: Beta | B10: 0.77359491

Sheet TheFund
A1: key | B1: value
A2: =Newsletter!AC126 -> Universe | B2: =Newsletter!AF126 -> Global
A3: =Newsletter!AC127 -> Holdings | B3: =Newsletter!AF127 -> 5-20
A4: =Newsletter!AC128 -> Target | B4: =Newsletter!AF128 -> >10% net p.a.
A5: =Newsletter!AC129 -> Min Investment | B5: =Newsletter!AF129 -> $100k
A6: =Newsletter!AC130 -> Mgmt. Fee | B6: =Newsletter!AF130 -> 0.01
A7: =Newsletter!AC131 -> Perf. Fee | B7: =Newsletter!AF131 -> 0.2
A8: =Newsletter!AC132 -> APIR | B8: =Newsletter!AF132 -> NCC5451AU
A9: =Newsletter!AC133 -> Vehicle | B9: =Newsletter!AF133 -> Wholesale Unit Trust
A10: =Newsletter!AC134 -> PM | B10: =Newsletter!AF134 -> Hayden Beamish

Sheet Exposure
A1: key | B1: value | D1: name | E1: value | G1: name | H1: value | I1: labels
A2: Gross long | B2: 0.524 | D2: CASH | E2: 0.62 | G2: >$10b | H2: 0.84 | I2: >$10b (84%)
A3: Gross short | B3: -0.0199 | D3: TECHNOLOGY | E3: 0.1379 | G3: $1b-$10b | H3: 0.11 | I3: $1b-$10b (11%)
A4: Net | B4: =B2+B3 -> 0.5041 | D4: MATERIALS | E4: 0.11 | G4: $500m-$1b | H4: 0 | I4: $500m-$1b (0%)
D5: FINANCIALS | E5: =0.1379-0.0598 -> 0.0781 | G5: $300m-$500m | H5: 0 | I5: $300m-$500m (0%)
D6: OTHER | E6: =1-SUM(E2:E5) -> 0.054 | G6: <$300m | H6: 0.05 | I6: <$300m (5%)

Sheet Text
A1: key | B1: text
A2: Strategy | B2: We run a concentrated, long biased portfolio of 5 to 20 positions, with flexibility to short mainly for hedging and risk management. We focus on quality businesses, sizing positions by conviction and risk reward, cutting losers quickly and letting winners compound. Ideas are sourced through deep fundamental research enhanced by proprietary AI analytics to uncover catalysts, growth themes and market dislocations. The Portfolio Manager is invested alongside clients.
A3: Hedging | B3: Hedging is part of our core process, not a trade. We aim to protect capital, smooth the return path and keep dry powder so we can play offence when others are forced to sell. We flex net exposure using index futures and options such as put spreads, collars and opportunistic call overwrites to neutralise market risk at low carry, add selective single name shorts where fundamentals are deteriorating or positioning is crowded, and hold cash when the opportunity set is thin.
A4: AI Analyst | B4: It ingests earnings calls, company filings, price and volume, options flow and credible web signals each day, then ranks what changed and why it matters. Language models flag guidance shifts, management tone, competitive pressure and anomalies that are easy to miss at speed, while pattern detection surfaces repeatable set ups and builds live watchlists with entry and exit levels, catalysts and risks. The output is concise one page briefs and scenario tests that support quicker and better sizing decisions. It augments our work, it does not decide, and every idea still passes a fundamental review before capital is risked.
A5: Risk Management | B5: We are return focused and drawdown aware. Risk is set before entry: every trade has defined downside, a stop loss, and a position size based on conviction, liquidity and risk reward within name and sector limits. Gross and net exposure sit inside bands, with hedges and shorts used to neutralise unintended risks. Liquidity comes first, supported by event playbooks and ongoing stress tests across rates, currency, factors and commodities; portfolio drawdown triggers force action. Independent trustee, administration and audit provide oversight with daily reconciliation, and the Portfolio Manager invests alongside clients.
